Workbook

Sheet Summary
A1: Fund Performance Overview
A3: Initial Capital | B3: =Assumptions!B4 -> 100000000
A4: Final Portfolio Value (30-Sep-2025) | B4: =Daily_Ledger!L93 -> 1.0168325e+08
A5: Total P&L | B5: =B4-B3 -> 1683253.7
A6: Risk Free Rate (Annual) | B6: =Assumptions!B5 -> 0.06
A7: Risk Free Rate (Daily) | B7: =B6/365 -> 0.00016438356
A8: Start Date | B8: =Assumptions!B7 -> 45839
A9: End Date | B9: =Assumptions!B8 -> 45930
A10: Project Days | B10: =B9-B8+1 -> 92
A12: Total Return (92 Days) | B12: =B5/B3 -> 0.016832537
A13: Annualized Return | B13: =B12*(365/B10) -> 0.066781261
A15: Benchmark Comparison
A17: Risk-Free Benchmark (Annual) | B17: =B6 -> 0.06
A18: Benchmark Return (92 Days) | B18: =(1+B17)^(B10/365)-1 -> 0.014795341
A19: Outperformance (Alpha) | B19: =B13-B17 -> 0.0067812614
A21: Strategy Rules
A23: Minimum Annualized Spread (Net) | B23: =Assumptions!B13 -> 0.0645
A24: Allocation per Trade (% of Cash) | B24: =Assumptions!B14 -> 0.45
A25: Max Allocation (% of Fund) | B25: =Assumptions!B15 -> 0.33
A26: Spot T-Cost | B26: =Assumptions!B16 -> 0.0005
A27: Futures T-Cost | B27: =Assumptions!B17 -> 0.0002
A28: Initial Margin (%) | B28: =Assumptions!B18 -> 0.2
A29: Cost of Carry (%) | B29: =Assumptions!B19 -> 0.005
A31: Asset Details
A33: Asset | B33: Lot Size
A34: RELIANCE | B34: =Assumptions!B24 -> 500
A35: ADANI | B35: =Assumptions!B25 -> 300
A37: Contract | B37: Expiry_Date
A38: JUL | B38: =Assumptions!B30 -> 45869
A39: AUG | B39: =Assumptions!B31 -> 45897
A40: SEP | B40: =Assumptions!B32 -> 45930
A42: Trade Statistics
A44: Total Arbitrage Trades Executed | B44: =COUNT(Trade_Log!A:A) -> 12
A45: Total Interest from Money Market | B45: =SUM(Daily_Ledger!H:H) -> 1199969.5
A46: Total P&L from Arbitrage Trades | B46: =B5-B45 -> 483284.17

Sheet Assumptions
A2: Fund Details
A4: Initial Capital | B4: 100000000
A5: Risk Free Rate (Annual) | B5: 0.06
A6: Risk Free Rate (Daily) | B6: =B5/365 -> 0.00016438356
A7: Start Date | B7: 45839
A8: End Date | B8: 45930
A9: Project Days | B9: =B8-B7+1 -> 92
A11: Strategy Rules
A13: Minimum Annualized Spread (Net) | B13: 0.0645
A14: Allocation per Trade (% of Cash) | B14: 0.45
A15: Max Allocation (% of Fund) | B15: 0.33
A16: Spot T-Cost | B16: 0.0005
A17: Futures T-Cost | B17: 0.0002
A18: Initial Margin (%) | B18: 0.2
A19: Cost of Carry (%) | B19: 0.005
A21: Asset Details
A23: Asset | B23: Lot Size
A24: RELIANCE | B24: 500
A25: ADANI | B25: 300
A27: Contract Details
A29: Contract | B29: Expiry_Date
A30: JUL | B30: 45869
A31: AUG | B31: 45897
A32: SEP | B32: 45930

Sheet Data Analysis
A1: Date | B1: Stock | C1: Spot_Price | D1: July_Futures_Price | E1: July_Expiry_Date | F1: Date To Expiry | G1: Fair Value | H1: Gross Spread | I1: Total_T-costs | J1: Net Profit | K1: Capital Blocked | L1: Net Return (%) | M1: Annualized_Return (%) | N1: TRADE_SIGNAL | P1: August_Futures_Price | Q1: August_Expiry_Date | R1: Date To Expiry | S1: Fair Value | T1: Gross Spread | U1: Total_T-costs | V1: Net Profit | W1: Capital Blocked | X1: Net Return (%) | Y1: Annualized_Return (%) | Z1: TRADE_SIGNAL | AB1: September_Futures_Price | AC1: September_Expiry_Date | AD1: Date To Expiry | AE1: Fair Value | AF1: Gross Spread | AG1: Total_T-costs | AH1: Net Profit | AI1: Capital Blocked | AJ1: Net Return (%) | AK1: Annualized_Return (%) | AL1: TRADE_SIGNAL
A2: 45839 | B2: RELIANCE | C2: =VLOOKUP(A2, Raw_Data_Reliance!A:N, 8, FALSE) -> 1528.4 | D2: =VLOOKUP(A2, Raw_Data_Reliance!O:AA, 8, FALSE) -> 1532.1 | E2: =Assumptions!$B$30 -> 45869 | F2: =E2-A2 -> 30 | G2: =C2*(1+(Assumptions!$B$19*F2/365)) -> 1529.0281 | H2: =D2-G2 -> 3.0718904 | I2: =(C2*Assumptions!$B$16)+(D2*Assumptions!$B$17) -> 1.07062 | J2: =H2-I2 -> 2.0012704 | K2: =C2+(D2*Assumptions!$B$15) -> 2033.993 | L2: =J2/K2 -> 0.00098391214 | M2: =L2*(365/F2) -> 0.011970931 | N2: =IF(AND(F2>0, M2 > Assumptions!$B$13), "ENTER", "DONT ENTER") -> DONT ENTER | P2: =VLOOKUP(A2, Raw_Data_Reliance!AB:AP, 8, FALSE) -> 1536.2 | Q2: =Assumptions!$B$31 -> 45897 | R2: =Q2-A2 -> 58 | S2: =C2*(1+(Assumptions!$B$19*R2/365)) -> 1529.6143 | T2: =P2-S2 -> 6.5856548 | U2: =(C2*Assumptions!$B$16)+(P2*Assumptions!$B$17) -> 1.07144 | V2: =T2-U2 -> 5.5142148 | W2: =C2+(P2*Assumptions!$B$15) -> 2035.346 | X2: =V2/W2 -> 0.0027092272 | Y2: =X2*(365/R2) -> 0.017049447 | Z2: =IF(AND(R2>0,Y2 > Assumptions!$B$13), "ENTER", "DONT ENTER") -> DONT ENTER | AB2: =VLOOKUP(A2, Raw_Data_Reliance!AQ:BE, 8, FALSE) -> 1544.4 | AC2: =Assumptions!$B$32 -> 45930 | AD2: =AC2-A2 -> 91 | AE2: =C2*(1+(Assumptions!$B$13*AD2/365)) -> 1552.9779 | AF2: =AB2-AE2 -> -8.5779282 | AG2: =(C2*Assumptions!$B$16)+(AB2*Assumptions!$B$17) -> 1.07308 | AH2: =AF2-AG2 -> -9.6510082 | AI2: =C2+(AB2*Assumptions!$B$15) -> 2038.052 | AJ2: =AH2/AI2 -> -0.0047354082 | AK2: =AJ2*(365/AD2) -> -0.01899367 | AL2: =IF(AND(AD2>0,AK2 > Assumptions!$B$13), "ENTER", "DONT ENTER") -> DONT ENTER
A3: 45840 | B3: RELIANCE | C3: =VLOOKUP(A3, Raw_Data_Reliance!A:N, 8, FALSE) -> 1518.8 | D3: =VLOOKUP(A3, Raw_Data_Reliance!O:AA, 8, FALSE) -> 1523.2 | E3: =Assumptions!$B$30 -> 45869 | F3: =E3-A3 -> 29 | G3: =C3*(1+(Assumptions!$B$19*F3/365)) -> 1519.4034 | H3: =D3-G3 -> 3.7966411 | I3: =(C3*Assumptions!$B$16)+(D3*Assumptions!$B$17) -> 1.06404 | J3: =H3-I3 -> 2.7326011 | K3: =C3+(D3*Assumptions!$B$15) -> 2021.456 | L3: =J3/K3 -> 0.0013517985 | M3: =L3*(365/F3) -> 0.017014015 | N3: =IF(AND(F3>0, M3 > Assumptions!$B$13), "ENTER", "DONT ENTER") -> DONT ENTER | P3: =VLOOKUP(A3, Raw_Data_Reliance!AB:AP, 8, FALSE) -> 1527 | Q3: =Assumptions!$B$31 -> 45897 | R3: =Q3-A3 -> 57 | S3: =C3*(1+(Assumptions!$B$19*R3/365)) -> 1519.9859 | T3: =P3-S3 -> 7.0140877 | U3: =(C3*Assumptions!$B$16)+(P3*Assumptions!$B$17) -> 1.0648 | V3: =T3-U3 -> 5.9492877 | W3: =C3+(P3*Assumptions!$B$15) -> 2022.71 | X3: =V3/W3 -> 0.002941246 | Y3: =X3*(365/R3) -> 0.018834294 | Z3: =IF(AND(R3>0,Y3 > Assumptions!$B$13), "ENTER", "DONT ENTER") -> DONT ENTER | AB3: =VLOOKUP(A3, Raw_Data_Reliance!AQ:BE, 8, FALSE) -> 1536 | AC3: =Assumptions!$B$32 -> 45930 | AD3: =AC3-A3 -> 90 | AE3: =C3*(1+(Assumptions!$B$13*AD3/365)) -> 1542.9552 | AF3: =AB3-AE3 -> -6.9551616 | AG3: =(C3*Assumptions!$B$16)+(AB3*Assumptions!$B$17) -> 1.0666 | AH3: =AF3-AG3 -> -8.0217616 | AI3: =C3+(AB3*Assumptions!$B$15) -> 2025.68 | AJ3: =AH3/AI3 -> -0.003960034 | AK3: =AJ3*(365/AD3) -> -0.016060138 | AL3: =IF(AND(AD3>0,AK3 > Assumptions!$B$13), "ENTER", "DONT ENTER") -> DONT ENTER
A4: 45841 | B4: RELIANCE | C4: =VLOOKUP(A4, Raw_Data_Reliance!A:N, 8, FALSE) -> 1517.8 | D4: =VLOOKUP(A4, Raw_Data_Reliance!O:AA, 8, FALSE) -> 1525.3 | E4: =Assumptions!$B$30 -> 45869 | F4: =E4-A4 -> 28 | G4: =C4*(1+(Assumptions!$B$19*F4/365)) -> 1518.3822 | H4: =D4-G4 -> 6.9178301 | I4: =(C4*Assumptions!$B$16)+(D4*Assumptions!$B$17) -> 1.06396 | J4: =H4-I4 -> 5.8538701 | K4: =C4+(D4*Assumptions!$B$15) -> 2021.149 | L4: =J4/K4 -> 0.0028963081 | M4: =L4*(365/F4) -> 0.037755444 | N4: =IF(AND(F4>0, M4 > Assumptions!$B$13), "ENTER", "DONT ENTER") -> DONT ENTER | P4: =VLOOKUP(A4, Raw_Data_Reliance!AB:AP, 8, FALSE) -> 1527.7 | Q4: =Assumptions!$B$31 -> 45897 | R4: =Q4-A4 -> 56 | S4: =C4*(1+(Assumptions!$B$19*R4/365)) -> 1518.9643 | T4: =P4-S4 -> 8.7356603 | U4: =(C4*Assumptions!$B$16)+(P4*Assumptions!$B$17) -> 1.06444 | V4: =T4-U4 -> 7.6712203 | W4: =C4+(P4*Assumptions!$B$15) -> 2021.941 | X4: =V4/W4 -> 0.0037939882 | Y4: =X4*(365/R4) -> 0.024728673 | Z4: =IF(AND(R4>0,Y4 > Assumptions!$B$13), "ENTER", "DONT ENTER") -> DONT ENTER | AB4: =VLOOKUP(A4, Raw_Data_Reliance!AQ:BE, 8, FALSE) -> 1537.8 | AC4: =Assumptions!$B$32 -> 45930 | AD4: =AC4-A4 -> 89 | AE4: =C4*(1+(Assumptions!$B$13*AD4/365)) -> 1541.671 | AF4: =AB4-AE4 -> -3.8710436 | AG4: =(C4*Assumptions!$B$16)+(AB4*Assumptions!$B$17) -> 1.06646 | AH4: =AF4-AG4 -> -4.9375036 | AI4: =C4+(AB4*Assumptions!$B$15) -> 2025.274 | AJ4: =AH4/AI4 -> -0.0024379435 | AK4: =AJ4*(365/AD4) -> -0.0099983076 | AL4: =IF(AND(AD4>0,AK4 > Assumptions!$B$13), "ENTER", "DONT ENTER") -> DONT ENTER
A5: 45842 | B5: RELIANCE | C5: =VLOOKUP(A5, Raw_Data_Reliance!A:N, 8, FALSE) -> 1527.3 | D5: =VLOOKUP(A5, Raw_Data_Reliance!O:AA, 8, FALSE) -> 1531.3 | E5: =Assumptions!$B$30 -> 45869 | F5: =E5-A5 -> 27 | G5: =C5*(1+(Assumptions!$B$19*F5/365)) -> 1527.8649 | H5: =D5-G5 -> 3.4351082 | I5: =(C5*Assumptions!$B$16)+(D5*Assumptions!$B$17) -> 1.06991 | J5: =H5-I5 -> 2.3651982 | K5: =C5+(D5*Assumptions!$B$15) -> 2032.629 | L5: =J5/K5 -> 0.0011636153 | M5: =L5*(365/F5) -> 0.015730355 | N5: =IF(AND(F5>0, M5 > Assumptions!$B$13), "ENTER", "DONT ENTER") -> DONT ENTER | P5: =VLOOKUP(A5, Raw_Data_Reliance!AB:AP, 8, FALSE) -> 1534.1 | Q5: =Assumptions!$B$31 -> 45897 | R5: =Q5-A5 -> 55 | S5: =C5*(1+(Assumptions!$B$19*R5/365)) -> 1528.4507 | T5: =P5-S5 -> 5.6492945 | U5: =(C5*Assumptions!$B$16)+(P5*Assumptions!$B$17) -> 1.07047 | V5: =T5-U5 -> 4.5788245 | W5: =C5+(P5*Assumptions!$B$15) -> 2033.553 | X5: =V5/W5 -> 0.0022516377 | Y5: =X5*(365/R5) -> 0.014942686 | Z5: =IF(AND(R5>0,Y5 > Assumptions!$B$13), "ENTER", "DONT ENTER") -> DONT ENTER | AB5: =VLOOKUP(A5, Raw_Data_Reliance!AQ:BE, 8, FALSE) -> 1543.3 | AC5: =Assumptions!$B$32 -> 45930 | AD5: =AC5-A5 -> 88 | AE5: =C5*(1+(Assumptions!$B$13*AD5/365)) -> 1551.0506 | AF5: =AB5-AE5 -> -7.7505611 | AG5: =(C5*Assumptions!$B$16)+(AB5*Assumptions!$B$17) -> 1.07231 | AH5: =AF5-AG5 -> -8.8228711 | AI5: =C5+(AB5*Assumptions!$B$15) -> 2036.589 | AJ5: =AH5/AI5 -> -0.0043321805 | AK5: =AJ5*(365/AD5) -> -0.017968703 | AL5: =IF(AND(AD5>0,AK5 > Assumptions!$B$13), "ENTER", "DONT ENTER") -> DONT ENTER
A6: 45843 | B6: RELIANCE | C6: =VLOOKUP(A6, Raw_Data_Reliance!A:N, 8, FALSE) -> #N/A | D6: =VLOOKUP(A6, Raw_Data_Reliance!O:AA, 8, FALSE) -> #N/A | E6: =Assumptions!$B$30 -> 45869 | F6: =E6-A6 -> 26 | G6: =C6*(1+(Assumptions!$B$19*F6/365)) -> #N/A | H6: =D6-G6 -> #N/A | I6: =(C6*Assumptions!$B$16)+(D6*Assumptions!$B$17) -> #N/A | J6: =H6-I6 -> #N/A | K6: =C6+(D6*Assumptions!$B$15) -> #N/A | L6: =J6/K6 -> #N/A | M6: =L6*(365/F6) -> #N/A | N6: =IF(AND(F6>0, M6 > Assumptions!$B$13), "ENTER", "DONT ENTER") -> #N/A | P6: =VLOOKUP(A6, Raw_Data_Reliance!AB:AP, 8, FALSE) -> #N/A | Q6: =Assumptions!$B$31 -> 45897 | R6: =Q6-A6 -> 54 | S6: =C6*(1+(Assumptions!$B$19*R6/365)) -> #N/A | T6: =P6-S6 -> #N/A | U6: =(C6*Assumptions!$B$16)+(P6*Assumptions!$B$17) -> #N/A | V6: =T6-U6 -> #N/A | W6: =C6+(P6*Assumptions!$B$15) -> #N/A | X6: =V6/W6 -> #N/A | Y6: =X6*(365/R6) -> #N/A | Z6: =IF(AND(R6>0,Y6 > Assumptions!$B$13), "ENTER", "DONT ENTER") -> #N/A | AB6: =VLOOKUP(A6, Raw_Data_Reliance!AQ:BE, 8, FALSE) -> #N/A | AC6: =Assumptions!$B$32 -> 45930 | AD6: =AC6-A6 -> 87 | AE6: =C6*(1+(Assumptions!$B$13*AD6/365)) -> #N/A | AF6: =AB6-AE6 -> #N/A | AG6: =(C6*Assumptions!$B$16)+(AB6*Assumptions!$B$17) -> #N/A | AH6: =AF6-AG6 -> #N/A | AI6: =C6+(AB6*Assumptions!$B$15) -> #N/A | AJ6: =AH6/AI6 -> #N/A | AK6: =AJ6*(365/AD6) -> #N/A | AL6: =IF(AND(AD6>0,AK6 > Assumptions!$B$13), "ENTER", "DONT ENTER") -> #N/A
A7: 45844 | B7: RELIANCE | C7: =VLOOKUP(A7, Raw_Data_Reliance!A:N, 8, FALSE) -> #N/A | D7: =VLOOKUP(A7, Raw_Data_Reliance!O:AA, 8, FALSE) -> #N/A | E7: =Assumptions!$B$30 -> 45869 | F7: =E7-A7 -> 25 | G7: =C7*(1+(Assumptions!$B$19*F7/365)) -> #N/A | H7: =D7-G7 -> #N/A | I7: =(C7*Assumptions!$B$16)+(D7*Assumptions!$B$17) -> #N/A | J7: =H7-I7 -> #N/A | K7: =C7+(D7*Assumptions!$B$15) -> #N/A | L7: =J7/K7 -> #N/A | M7: =L7*(365/F7) -> #N/A | N7: =IF(AND(F7>0, M7 > Assumptions!$B$13), "ENTER", "DONT ENTER") -> #N/A | P7: =VLOOKUP(A7, Raw_Data_Reliance!AB:AP, 8, FALSE) -> #N/A | Q7: =Assumptions!$B$31 -> 45897 | R7: =Q7-A7 -> 53 | S7: =C7*(1+(Assumptions!$B$19*R7/365)) -> #N/A | T7: =P7-S7 -> #N/A | U7: =(C7*Assumptions!$B$16)+(P7*Assumptions!$B$17) -> #N/A | V7: =T7-U7 -> #N/A | W7: =C7+(P7*Assumptions!$B$15) -> #N/A | X7: =V7/W7 -> #N/A | Y7: =X7*(365/R7) -> #N/A | Z7: =IF(AND(R7>0,Y7 > Assumptions!$B$13), "ENTER", "DONT ENTER") -> #N/A | AB7: =VLOOKUP(A7, Raw_Data_Reliance!AQ:BE, 8, FALSE) -> #N/A | AC7: =Assumptions!$B$32 -> 45930 | AD7: =AC7-A7 -> 86 | AE7: =C7*(1+(Assumptions!$B$13*AD7/365)) -> #N/A | AF7: =AB7-AE7 -> #N/A | AG7: =(C7*Assumptions!$B$16)+(AB7*Assumptions!$B$17) -> #N/A | AH7: =AF7-AG7 -> #N/A | AI7: =C7+(AB7*Assumptions!$B$15) -> #N/A | AJ7: =AH7/AI7 -> #N/A | AK7: =AJ7*(365/AD7) -> #N/A | AL7: =IF(AND(AD7>0,AK7 > Assumptions!$B$13), "ENTER", "DONT ENTER") -> #N/A
A8: 45845 | B8: RELIANCE | C8: =VLOOKUP(A8, Raw_Data_Reliance!A:N, 8, FALSE) -> 1541.5 | D8: =VLOOKUP(A8, Raw_Data_Reliance!O:AA, 8, FALSE) -> 1544.5 | E8: =Assumptions!$B$30 -> 45869 | F8: =E8-A8 -> 24 | G8: =C8*(1+(Assumptions!$B$19*F8/365)) -> 1542.0068 | H8: =D8-G8 -> 2.4932055 | I8: =(C8*Assumptions!$B$16)+(D8*Assumptions!$B$17) -> 1.07965 | J8: =H8-I8 -> 1.4135555 | K8: =C8+(D8*Assumptions!$B$15) -> 2051.185 | L8: =J8/K8 -> 0.0006891409 | M8: =L8*(365/F8) -> 0.010480685 | N8: =IF(AND(F8>0, M8 > Assumptions!$B$13), "ENTER", "DONT ENTER") -> DONT ENTER | P8: =VLOOKUP(A8, Raw_Data_Reliance!AB:AP, 8, FALSE) -> 1547.5 | Q8: =Assumptions!$B$31 -> 45897 | R8: =Q8-A8 -> 52 | S8: =C8*(1+(Assumptions!$B$19*R8/365)) -> 1542.5981 | T8: =P8-S8 -> 4.9019452 | U8: =(C8*Assumptions!$B$16)+(P8*Assumptions!$B$17) -> 1.08025 | V8: =T8-U8 -> 3.8216952 | W8: =C8+(P8*Assumptions!$B$15) -> 2052.175 | X8: =V8/W8 -> 0.0018622657 | Y8: =X8*(365/R8) -> 0.013071673 | Z8: =IF(AND(R8>0,Y8 > Assumptions!$B$13), "ENTER", "DONT ENTER") -> DONT ENTER | AB8: =VLOOKUP(A8, Raw_Data_Reliance!AQ:BE, 8, FALSE) -> 1555.6 | AC8: =Assumptions!$B$32 -> 45930 | AD8: =AC8-A8 -> 85 | AE8: =C8*(1+(Assumptions!$B$13*AD8/365)) -> 1564.6542 | AF8: =AB8-AE8 -> -9.0541747 | AG8: =(C8*Assumptions!$B$16)+(AB8*Assumptions!$B$17) -> 1.08187 | AH8: =AF8-AG8 -> -10.136045 | AI8: =C8+(AB8*Assumptions!$B$15) -> 2054.848 | AJ8: =AH8/AI8 -> -0.0049327467 | AK8: =AJ8*(365/AD8) -> -0.021181795 | AL8: =IF(AND(AD8>0,AK8 > Assumptions!$B$13), "ENTER", "DONT ENTER") -> DONT ENTER
A9: 45846 | B9: RELIANCE | C9: =VLOOKUP(A9, Raw_Data_Reliance!A:N, 8, FALSE) -> 1537.6 | D9: =VLOOKUP(A9, Raw_Data_Reliance!O:AA, 8, FALSE) -> 1545.1 | E9: =Assumptions!$B$30 -> 45869 | F9: =E9-A9 -> 23 | G9: =C9*(1+(Assumptions!$B$19*F9/365)) -> 1538.0844 | H9: =D9-G9 -> 7.0155507 | I9: =(C9*Assumptions!$B$16)+(D9*Assumptions!$B$17) -> 1.07782 | J9: =H9-I9 -> 5.9377307 | K9: =C9+(D9*Assumptions!$B$15) -> 2047.483 | L9: =J9/K9 -> 0.0029000146 | M9: =L9*(365/F9) -> 0.046021972 | N9: =IF(AND(F9>0, M9 > Assumptions!$B$13), "ENTER", "DONT ENTER") -> DONT ENTER | P9: =VLOOKUP(A9, Raw_Data_Reliance!AB:AP, 8, FALSE) -> 1547.6 | Q9: =Assumptions!$B$31 -> 45897 | R9: =Q9-A9 -> 51 | S9: =C9*(1+(Assumptions!$B$19*R9/365)) -> 1538.6742 | T9: =P9-S9 -> 8.9257863 | U9: =(C9*Assumptions!$B$16)+(P9*Assumptions!$B$17) -> 1.07832 | V9: =T9-U9 -> 7.8474663 | W9: =C9+(P9*Assumptions!$B$15) -> 2048.308 | X9: =V9/W9 -> 0.0038311945 | Y9: =X9*(365/R9) -> 0.027419333 | Z9: =IF(AND(R9>0,Y9 > Assumptions!$B$13), "ENTER", "DONT ENTER") -> DONT ENTER | AB9: =VLOOKUP(A9, Raw_Data_Reliance!AQ:BE, 8, FALSE) -> 1556.8 | AC9: =Assumptions!$B$32 -> 45930 | AD9: =AC9-A9 -> 84 | AE9: =C9*(1+(Assumptions!$B$13*AD9/365)) -> 1560.4239 | AF9: =AB9-AE9 -> -3.6238816 | AG9: =(C9*Assumptions!$B$16)+(AB9*Assumptions!$B$17) -> 1.08016 | AH9: =AF9-AG9 -> -4.7040416 | AI9: =C9+(AB9*Assumptions!$B$15) -> 2051.344 | AJ9: =AH9/AI9 -> -0.002293151 | AK9: =AJ9*(365/AD9) -> -0.0099642873 | AL9: =IF(AND(AD9>0,AK9 > Assumptions!$B$13), "ENTER", "DONT ENTER") -> DONT ENTER
A10: 45847 | B10: RELIANCE | C10: =VLOOKUP(A10, Raw_Data_Reliance!A:N, 8, FALSE) -> 1519 | D10: =VLOOKUP(A10, Raw_Data_Reliance!O:AA, 8, FALSE) -> 1524.6 | E10: =Assumptions!$B$30 -> 45869 | F10: =E10-A10 -> 22 | G10: =C10*(1+(Assumptions!$B$19*F10/365)) -> 1519.4578 | H10: =D10-G10 -> 5.1422192 | I10: =(C10*Assumptions!$B$16)+(D10*Assumptions!$B$17) -> 1.06442 | J10: =H10-I10 -> 4.0777992 | K10: =C10+(D10*Assumptions!$B$15) -> 2022.118 | L10: =J10/K10 -> 0.002016598 | M10: =L10*(365/F10) -> 0.033457195 | N10: =IF(AND(F10>0, M10 > Assumptions!$B$13), "ENTER", "DONT ENTER") -> DONT ENTER | P10: =VLOOKUP(A10, Raw_Data_Reliance!AB:AP, 8, FALSE) -> 1528.1 | Q10: =Assumptions!$B$31 -> 45897 | R10: =Q10-A10 -> 50 | S10: =C10*(1+(Assumptions!$B$19*R10/365)) -> 1520.0404 | T10: =P10-S10 -> 8.059589 | U10: =(C10*Assumptions!$B$16)+(P10*Assumptions!$B$17) -> 1.06512 | V10: =T10-U10 -> 6.994469 | W10: =C10+(P10*Assumptions!$B$15) -> 2023.273 | X10: =V10/W10 -> 0.0034570071 | Y10: =X10*(365/R10) -> 0.025236152 | Z10: =IF(AND(R10>0,Y10 > Assumptions!$B$13), "ENTER", "DONT ENTER") -> DONT ENTER | AB10: =VLOOKUP(A10, Raw_Data_Reliance!AQ:BE, 8, FALSE) -> 1538.1 | AC10: =Assumptions!$B$32 -> 45930 | AD10: =AC10-A10 -> 83 | AE10: =C10*(1+(Assumptions!$B$13*AD10/365)) -> 1541.2794 | AF10: =AB10-AE10 -> -3.1793603 | AG10: =(C10*Assumptions!$B$16)+(AB10*Assumptions!$B$17) -> 1.06712 | AH10: =AF10-AG10 -> -4.2464803 | AI10: =C10+(AB10*Assumptions!$B$15) -> 2026.573 | AJ10: =AH10/AI10 -> -0.0020953996 | AK10: =AJ10*(365/AD10) -> -0.0092147091 | AL10: =IF(AND(AD10>0,AK10 > Assumptions!$B$13), "ENTER", "DONT ENTER") -> DONT ENTER
A11: 45848 | B11: RELIANCE | C11: =VLOOKUP(A11, Raw_Data_Reliance!A:N, 8, FALSE) -> 1517.2 | D11: =VLOOKUP(A11, Raw_Data_Reliance!O:AA, 8, FALSE) -> 1519.7 | E11: =Assumptions!$B$30 -> 45869 | F11: =E11-A11 -> 21 | G11: =C11*(1+(Assumptions!$B$19*F11/365)) -> 1517.6365 | H11: =D11-G11 -> 2.0635452 | I11: =(C11*Assumptions!$B$16)+(D11*Assumptions!$B$17) -> 1.06254 | J11: =H11-I11 -> 1.0010052 | K11: =C11+(D11*Assumptions!$B$15) -> 2018.701 | L11: =J11/K11 -> 0.00049586601 | M11: =L11*(365/F11) -> 0.0086186235 | N11: =IF(AND(F11>0, M11 > Assumptions!$B$13), "ENTER", "DONT ENTER") -> DONT ENTER | P11: =VLOOKUP(A11, Raw_Data_Reliance!AB:AP, 8, FALSE) -> 1522.5 | Q11: =Assumptions!$B$31 -> 45897 | R11: =Q11-A11 -> 49 | S11: =C11*(1+(Assumptions!$B$19*R11/365)) -> 1518.2184 | T11: =P11-S11 -> 4.2816055 | U11: =(C11*Assumptions!$B$16)+(P11*Assumptions!$B$17) -> 1.0631 | V11: =T11-U11 -> 3.2185055 | W11: =C11+(P11*Assumptions!$B$15) -> 2019.625 | X11: =V11/W11 -> 0.0015936154 | Y11: =X11*(365/R11) -> 0.011870809 | Z11: =IF(AND(R11>0,Y11 > Assumptions!$B$13), "ENTER", "DONT ENTER") -> DONT ENTER | AB11: =VLOOKUP(A11, Raw_Data_Reliance!AQ:BE, 8, FALSE) -> 1532.1 | AC11: =Assumptions!$B$32 -> 45930 | AD11: =AC11-A11 -> 82 | AE11: =C11*(1+(Assumptions!$B$13*AD11/365)) -> 1539.1849 | AF11: =AB11-AE11 -> -7.0848515 | AG11: =(C11*Assumptions!$B$16)+(AB11*Assumptions!$B$17) -> 1.06502 | AH11: =AF11-AG11 -> -8.1498715 | AI11: =C11+(AB11*Assumptions!$B$15) -> 2022.793 | AJ11: =AH11/AI11 -> -0.004029019 | AK11: =AJ11*(365/AD11) -> -0.017934048 | AL11: =IF(AND(AD11>0,AK11 > Assumptions!$B$13), "ENTER", "DONT ENTER") -> DONT ENTER
A12: 45849 | B12: RELIANCE | C12: =VLOOKUP(A12, Raw_Data_Reliance!A:N, 8, FALSE) -> 1495.2 | D12: =VLOOKUP(A12, Raw_Data_Reliance!O:AA, 8, FALSE) -> 1500.7 | E12: =Assumptions!$B$30 -> 45869 | F12: =E12-A12 -> 20 | G12: =C12*(1+(Assumptions!$B$19*F12/365)) -> 1495.6096 | H12: =D12-G12 -> 5.0903562 | I12: =(C12*Assumptions!$B$16)+(D12*Assumptions!$B$17) -> 1.04774 | J12: =H12-I12 -> 4.0426162 | K12: =C12+(D12*Assumptions!$B$15) -> 1990.431 | L12: =J12/K12 -> 0.0020310255 | M12: =L12*(365/F12) -> 0.037066216 | N12: =IF(AND(F12>0, M12 > Assumptions!$B$13), "ENTER", "DONT ENTER") -> DONT ENTER | P12: =VLOOKUP(A12, Raw_Data_Reliance!AB:AP, 8, FALSE) -> 1503.3 | Q12: =Assumptions!$B$31 -> 45897 | R12: =Q12-A12 -> 48 | S12: =C12*(1+(Assumptions!$B$19*R12/365)) -> 1496.1831 | T12: =P12-S12 -> 7.1168548 | U12: =(C12*Assumptions!$B$16)+(P12*Assumptions!$B$17) -> 1.04826 | V12: =T12-U12 -> 6.0685948 | W12: =C12+(P12*Assumptions!$B$15) -> 1991.289 | X12: =V12/W12 -> 0.0030475711 | Y12: =X12*(365/R12) -> 0.023174239 | Z12: =IF(AND(R12>0,Y12 > Assumptions!$B$13), "ENTER", "DONT ENTER") -> DONT ENTER | AB12: =VLOOKUP(A12, Raw_Data_Reliance!AQ:BE, 8, FALSE) -> 1512.2 | AC12: =Assumptions!$B$32 -> 45930 | AD12: =AC12-A12 -> 81 | AE12: =C12*(1+(Assumptions!$B$13*AD12/365)) -> 1516.6018 | AF12: =AB12-AE12 -> -4.4018422 | AG12: =(C12*Assumptions!$B$16)+(AB12*Assumptions!$B$17) -> 1.05004 | AH12: =AF12-AG12 -> -5.4518822 | AI12: =C12+(AB12*Assumptions!$B$15) -> 1994.226 | AJ12: =AH12/AI12 -> -0.0027338337 | AK12: =AJ12*(365/AD12) -> -0.012319127 | AL12: =IF(AND(AD12>0,AK12 > Assumptions!$B$13), "ENTER", "DONT ENTER") -> DONT ENTER
A13: 45850 | B13: RELIANCE | C13: =VLOOKUP(A13, Raw_Data_Reliance!A:N, 8, FALSE) -> #N/A | D13: =VLOOKUP(A13, Raw_Data_Reliance!O:AA, 8, FALSE) -> #N/A | E13: =Assumptions!$B$30 -> 45869 | F13: =E13-A13 -> 19 | G13: =C13*(1+(Assumptions!$B$19*F13/365)) -> #N/A | H13: =D13-G13 -> #N/A | I13: =(C13*Assumptions!$B$16)+(D13*Assumptions!$B$17) -> #N/A | J13: =H13-I13 -> #N/A | K13: =C13+(D13*Assumptions!$B$15) -> #N/A | L13: =J13/K13 -> #N/A | M13: =L13*(365/F13) -> #N/A | N13: =IF(AND(F13>0, M13 > Assumptions!$B$13), "ENTER", "DONT ENTER") -> #N/A | P13: =VLOOKUP(A13, Raw_Data_Reliance!AB:AP, 8, FALSE) -> #N/A | Q13: =Assumptions!$B$31 -> 45897 | R13: =Q13-A13 -> 47 | S13: =C13*(1+(Assumptions!$B$19*R13/365)) -> #N/A | T13: =P13-S13 -> #N/A | U13: =(C13*Assumptions!$B$16)+(P13*Assumptions!$B$17) -> #N/A | V13: =T13-U13 -> #N/A | W13: =C13+(P13*Assumptions!$B$15) -> #N/A | X13: =V13/W13 -> #N/A | Y13: =X13*(365/R13) -> #N/A | Z13: =IF(AND(R13>0,Y13 > Assumptions!$B$13), "ENTER", "DONT ENTER") -> #N/A | AB13: =VLOOKUP(A13, Raw_Data_Reliance!AQ:BE, 8, FALSE) -> #N/A | AC13: =Assumptions!$B$32 -> 45930 | AD13: =AC13-A13 -> 80 | AE13: =C13*(1+(Assumptions!$B$13*AD13/365)) -> #N/A | AF13: =AB13-AE13 -> #N/A | AG13: =(C13*Assumptions!$B$16)+(AB13*Assumptions!$B$17) -> #N/A | AH13: =AF13-AG13 -> #N/A | AI13: =C13+(AB13*Assumptions!$B$15) -> #N/A | AJ13: =AH13/AI13 -> #N/A | AK13: =AJ13*(365/AD13) -> #N/A | AL13: =IF(AND(AD13>0,AK13 > Assumptions!$B$13), "ENTER", "DONT ENTER") -> #N/A
... A32: 45869 | B32: RELIANCE | C32: =VLOOKUP(A32, Raw_Data_Reliance!A:N, 8, FALSE) -> 1390.2 | D32: =VLOOKUP(A32, Raw_Data_Reliance!O:AA, 8, FALSE) -> 1390.2 | E32: =Assumptions!$B$30 -> 45869 | F32: =E32-A32 -> 0 | G32: =C32*(1+(Assumptions!$B$19*F32/365)) -> 1390.2 | H32: =D32-G32 -> 0 | I32: =(C32*Assumptions!$B$16)+(D32*Assumptions!$B$17) -> 0.97314 | J32: =H32-I32 -> -0.97314 | K32: =C32+(D32*Assumptions!$B$15) -> 1848.966 | L32: =J32/K32 -> -0.00052631579 | M32: =L32*(365/F32) -> #DIV/0! | N32: =IF(AND(F32>0, M32 > Assumptions!$B$13), "ENTER", "DONT ENTER") -> #DIV/0! | P32: =VLOOKUP(A32, Raw_Data_Reliance!AB:AP, 8, FALSE) -> 1393.9 | Q32: =Assumptions!$B$31 -> 45897 | R32: =Q32-A32 -> 28 | S32: =C32*(1+(Assumptions!$B$19*R32/365)) -> 1390.7332 | T32: =P32-S32 -> 3.1667726 | U32: =(C32*Assumptions!$B$16)+(P32*Assumptions!$B$17) -> 0.97388 | V32: =T32-U32 -> 2.1928926 | W32: =C32+(P32*Assumptions!$B$15) -> 1850.187 | X32: =V32/W32 -> 0.0011852275 | Y32: =X32*(365/R32) -> 0.015450288 | Z32: =IF(AND(R32>0,Y32 > Assumptions!$B$13), "ENTER", "DONT ENTER") -> DONT ENTER | AB32: =VLOOKUP(A32, Raw_Data_Reliance!AQ:BE, 8, FALSE) -> 1400.5 | AC32: =Assumptions!$B$32 -> 45930 | AD32: =AC32-A32 -> 61 | AE32: =C32*(1+(Assumptions!$B$13*AD32/365)) -> 1405.1856 | AF32: =AB32-AE32 -> -4.6855942 | AG32: =(C32*Assumptions!$B$16)+(AB32*Assumptions!$B$17) -> 0.9752 | AH32: =AF32-AG32 -> -5.6607942 | AI32: =C32+(AB32*Assumptions!$B$15) -> 1852.365 | AJ32: =AH32/AI32 -> -0.0030559821 | AK32: =AJ32*(365/AD32) -> -0.018285794 | AL32: =IF(AND(AD32>0,AK32 > Assumptions!$B$13), "ENTER", "DONT ENTER") -> DONT ENTER
A33: 45870 | B33: RELIANCE | C33: =VLOOKUP(A33, Raw_Data_Reliance!A:N, 8, FALSE) -> 1393.7 | P33: =VLOOKUP(A33, Raw_Data_Reliance!AB:AP, 8, FALSE) -> 1392.9 | Q33: =Assumptions!$B$31 -> 45897 | R33: =Q33-A33 -> 27 | S33: =C33*(1+(Assumptions!$B$19*R33/365)) -> 1394.2155 | T33: =P33-S33 -> -1.3154781 | U33: =(C33*Assumptions!$B$16)+(P33*Assumptions!$B$17) -> 0.97543 | V33: =T33-U33 -> -2.2909081 | W33: =C33+(P33*Assumptions!$B$15) -> 1853.357 | X33: =V33/W33 -> -0.0012360857 | Y33: =X33*(365/R33) -> -0.016710047 | Z33: =IF(AND(R33>0,Y33 > Assumptions!$B$13), "ENTER", "DONT ENTER") -> DONT ENTER | AB33: =VLOOKUP(A33, Raw_Data_Reliance!AQ:BE, 8, FALSE) -> 1400.6 | AC33: =Assumptions!$B$32 -> 45930 | AD33: =AC33-A33 -> 60 | AE33: =C33*(1+(Assumptions!$B$13*AD33/365)) -> 1408.477 | AF33: =AB33-AE33 -> -7.8770384 | AG33: =(C33*Assumptions!$B$16)+(AB33*Assumptions!$B$17) -> 0.97697 | AH33: =AF33-AG33 -> -8.8540084 | AI33: =C33+(AB33*Assumptions!$B$15) -> 1855.898 | AJ33: =AH33/AI33 -> -0.0047707408 | AK33: =AJ33*(365/AD33) -> -0.029022007 | AL33: =IF(AND(AD33>0,AK33 > Assumptions!$B$13), "ENTER", "DONT ENTER") -> DONT ENTER
A34: 45871 | B34: RELIANCE | C34: =VLOOKUP(A34, Raw_Data_Reliance!A:N, 8, FALSE) -> #N/A | P34: =VLOOKUP(A34, Raw_Data_Reliance!AB:AP, 8, FALSE) -> #N/A | Q34: =Assumptions!$B$31 -> 45897 | R34: =Q34-A34 -> 26 | S34: =C34*(1+(Assumptions!$B$19*R34/365)) -> #N/A | T34: =P34-S34 -> #N/A | U34: =(C34*Assumptions!$B$16)+(P34*Assumptions!$B$17) -> #N/A | V34: =T34-U34 -> #N/A | W34: =C34+(P34*Assumptions!$B$15) -> #N/A | X34: =V34/W34 -> #N/A | Y34: =X34*(365/R34) -> #N/A | Z34: =IF(AND(R34>0,Y34 > Assumptions!$B$13), "ENTER", "DONT ENTER") -> #N/A | AB34: =VLOOKUP(A34, Raw_Data_Reliance!AQ:BE, 8, FALSE) -> #N/A | AC34: =Assumptions!$B$32 -> 45930 | AD34: =AC34-A34 -> 59 | AE34: =C34*(1+(Assumptions!$B$13*AD34/365)) -> #N/A | AF34: =AB34-AE34 -> #N/A | AG34: =(C34*Assumptions!$B$16)+(AB34*Assumptions!$B$17) -> #N/A | AH34: =AF34-AG34 -> #N/A | AI34: =C34+(AB34*Assumptions!$B$15) -> #N/A | AJ34: =AH34/AI34 -> #N/A | AK34: =AJ34*(365/AD34) -> #N/A | AL34: =IF(AND(AD34>0,AK34 > Assumptions!$B$13), "ENTER", "DONT ENTER") -> #N/A
A35: 45872 | B35: RELIANCE | C35: =VLOOKUP(A35, Raw_Data_Reliance!A:N, 8, FALSE) -> #N/A | P35: =VLOOKUP(A35, Raw_Data_Reliance!AB:AP, 8, FALSE) -> #N/A | Q35: =Assumptions!$B$31 -> 45897 | R35: =Q35-A35 -> 25 | S35: =C35*(1+(Assumptions!$B$19*R35/365)) -> #N/A | T35: =P35-S35 -> #N/A | U35: =(C35*Assumptions!$B$16)+(P35*Assumptions!$B$17) -> #N/A | V35: =T35-U35 -> #N/A | W35: =C35+(P35*Assumptions!$B$15) -> #N/A | X35: =V35/W35 -> #N/A | Y35: =X35*(365/R35) -> #N/A | Z35: =IF(AND(R35>0,Y35 > Assumptions!$B$13), "ENTER", "DONT ENTER") -> #N/A | AB35: =VLOOKUP(A35, Raw_Data_Reliance!AQ:BE, 8, FALSE) -> #N/A | AC35: =Assumptions!$B$32 -> 45930 | AD35: =AC35-A35 -> 58 | AE35: =C35*(1+(Assumptions!$B$13*AD35/365)) -> #N/A | AF35: =AB35-AE35 -> #N/A | AG35: =(C35*Assumptions!$B$16)+(AB35*Assumptions!$B$17) -> #N/A | AH35: =AF35-AG35 -> #N/A | AI35: =C35+(AB35*Assumptions!$B$15) -> #N/A | AJ35: =AH35/AI35 -> #N/A | AK35: =AJ35*(365/AD35) -> #N/A | AL35: =IF(AND(AD35>0,AK35 > Assumptions!$B$13), "ENTER", "DONT ENTER") -> #N/A
A36: 45873 | B36: RELIANCE | C36: =VLOOKUP(A36, Raw_Data_Reliance!A:N, 8, FALSE) -> 1411.5 | P36: =VLOOKUP(A36, Raw_Data_Reliance!AB:AP, 8, FALSE) -> 1409.9 | Q36: =Assumptions!$B$31 -> 45897 | R36: =Q36-A36 -> 24 | S36: =C36*(1+(Assumptions!$B$19*R36/365)) -> 1411.9641 | T36: =P36-S36 -> -2.0640548 | U36: =(C36*Assumptions!$B$16)+(P36*Assumptions!$B$17) -> 0.98773 | V36: =T36-U36 -> -3.0517848 | W36: =C36+(P36*Assumptions!$B$15) -> 1876.767 | X36: =V36/W36 -> -0.0016260861 | Y36: =X36*(365/R36) -> -0.02473006 | Z36: =IF(AND(R36>0,Y36 > Assumptions!$B$13), "ENTER", "DONT ENTER") -> DONT ENTER | AB36: =VLOOKUP(A36, Raw_Data_Reliance!AQ:BE, 8, FALSE) -> 1417.5 | AC36: =Assumptions!$B$32 -> 45930 | AD36: =AC36-A36 -> 57 | AE36: =C36*(1+(Assumptions!$B$13*AD36/365)) -> 1425.7175 | AF36: =AB36-AE36 -> -8.2174788 | AG36: =(C36*Assumptions!$B$16)+(AB36*Assumptions!$B$17) -> 0.98925 | AH36: =AF36-AG36 -> -9.2067288 | AI36: =C36+(AB36*Assumptions!$B$15) -> 1879.275 | AJ36: =AH36/AI36 -> -0.0048990854 | AK36: =AJ36*(365/AD36) -> -0.031371337 | AL36: =IF(AND(AD36>0,AK36 > Assumptions!$B$13), "ENTER", "DONT ENTER") -> DONT ENTER
A37: 45874 | B37: RELIANCE | C37: =VLOOKUP(A37, Raw_Data_Reliance!A:N, 8, FALSE) -> 1391.7 | P37: =VLOOKUP(A37, Raw_Data_Reliance!AB:AP, 8, FALSE) -> 1389.9 | Q37: =Assumptions!$B$31 -> 45897 | R37: =Q37-A37 -> 23 | S37: =C37*(1+(Assumptions!$B$19*R37/365)) -> 1392.1385 | T37: =P37-S37 -> -2.2384808 | U37: =(C37*Assumptions!$B$16)+(P37*Assumptions!$B$17) -> 0.97383 | V37: =T37-U37 -> -3.2123108 | W37: =C37+(P37*Assumptions!$B$15) -> 1850.367 | X37: =V37/W37 -> -0.0017360398 | Y37: =X37*(365/R37) -> -0.027550197 | Z37: =IF(AND(R37>0,Y37 > Assumptions!$B$13), "ENTER", "DONT ENTER") -> DONT ENTER | AB37: =VLOOKUP(A37, Raw_Data_Reliance!AQ:BE, 8, FALSE) -> 1398.3 | AC37: =Assumptions!$B$32 -> 45930 | AD37: =AC37-A37 -> 56 | AE37: =C37*(1+(Assumptions!$B$13*AD37/365)) -> 1405.4721 | AF37: =AB37-AE37 -> -7.1721107 | AG37: =(C37*Assumptions!$B$16)+(AB37*Assumptions!$B$17) -> 0.97551 | AH37: =AF37-AG37 -> -8.1476207 | AI37: =C37+(AB37*Assumptions!$B$15) -> 1853.139 | AJ37: =AH37/AI37 -> -0.0043966592 | AK37: =AJ37*(365/AD37) -> -0.028656797 | AL37: =IF(AND(AD37>0,AK37 > Assumptions!$B$13), "ENTER", "DONT ENTER") -> DONT ENTER
A38: 45875 | B38: RELIANCE | C38: =VLOOKUP(A38, Raw_Data_Reliance!A:N, 8, FALSE) -> 1392.8 | P38: =VLOOKUP(A38, Raw_Data_Reliance!AB:AP, 8, FALSE) -> 1393.5 | Q38: =Assumptions!$B$31 -> 45897 | R38: =Q38-A38 -> 22 | S38: =C38*(1+(Assumptions!$B$19*R38/365)) -> 1393.2197 | T38: =P38-S38 -> 0.28025205 | U38: =(C38*Assumptions!$B$16)+(P38*Assumptions!$B$17) -> 0.9751 | V38: =T38-U38 -> -0.69484795 | W38: =C38+(P38*Assumptions!$B$15) -> 1852.655 | X38: =V38/W38 -> -0.00037505523 | Y38: =X38*(365/R38) -> -0.0062225072 | Z38: =IF(AND(R38>0,Y38 > Assumptions!$B$13), "ENTER", "DONT ENTER") -> DONT ENTER | AB38: =VLOOKUP(A38, Raw_Data_Reliance!AQ:BE, 8, FALSE) -> 1401.4 | AC38: =Assumptions!$B$32 -> 45930 | AD38: =AC38-A38 -> 55 | AE38: =C38*(1+(Assumptions!$B$13*AD38/365)) -> 1406.3369 | AF38: =AB38-AE38 -> -4.9368712 | AG38: =(C38*Assumptions!$B$16)+(AB38*Assumptions!$B$17) -> 0.97668 | AH38: =AF38-AG38 -> -5.9135512 | AI38: =C38+(AB38*Assumptions!$B$15) -> 1855.262 | AJ38: =AH38/AI38 -> -0.003187448 | AK38: =AJ38*(365/AD38) -> -0.021153064 | AL38: =IF(AND(AD38>0,AK38 > Assumptions!$B$13), "ENTER", "DONT ENTER") -> DONT ENTER
A39: 45876 | B39: RELIANCE | C39: =VLOOKUP(A39, Raw_Data_Reliance!A:N, 8, FALSE) -> 1389.4 | P39: =VLOOKUP(A39, Raw_Data_Reliance!AB:AP, 8, FALSE) -> 1390.6 | Q39: =Assumptions!$B$31 -> 45897 | R39: =Q39-A39 -> 21 | S39: =C39*(1+(Assumptions!$B$19*R39/365)) -> 1389.7997 | T39: =P39-S39 -> 0.80030959 | U39: =(C39*Assumptions!$B$16)+(P39*Assumptions!$B$17) -> 0.97282 | V39: =T39-U39 -> -0.17251041 | W39: =C39+(P39*Assumptions!$B$15) -> 1848.298 | X39: =V39/W39 -> -9.3334739e-05 | Y39: =X39*(365/R39) -> -0.0016222466 | Z39: =IF(AND(R39>0,Y39 > Assumptions!$B$13), "ENTER", "DONT ENTER") -> DONT ENTER | AB39: =VLOOKUP(A39, Raw_Data_Reliance!AQ:BE, 8, FALSE) -> 1398.3 | AC39: =Assumptions!$B$32 -> 45930 | AD39: =AC39-A39 -> 54 | AE39: =C39*(1+(Assumptions!$B$13*AD39/365)) -> 1402.6583 | AF39: =AB39-AE39 -> -4.3583019 | AG39: =(C39*Assumptions!$B$16)+(AB39*Assumptions!$B$17) -> 0.97436 | AH39: =AF39-AG39 -> -5.3326619 | AI39: =C39+(AB39*Assumptions!$B$15) -> 1850.839 | AJ39: =AH39/AI39 -> -0.0028812133 | AK39: =AJ39*(365/AD39) -> -0.019474868 | AL39: =IF(AND(AD39>0,AK39 > Assumptions!$B$13), "ENTER", "DONT ENTER") -> DONT ENTER
A40: 45877 | B40: RELIANCE | C40: =VLOOKUP(A40, Raw_Data_Reliance!A:N, 8, FALSE) -> 1367.8 | P40: =VLOOKUP(A40, Raw_Data_Reliance!AB:AP, 8, FALSE) -> 1368.3 | Q40: =Assumptions!$B$31 -> 45897 | R40: =Q40-A40 -> 20 | S40: =C40*(1+(Assumptions!$B$19*R40/365)) -> 1368.1747 | T40: =P40-S40 -> 0.12526027 | U40: =(C40*Assumptions!$B$16)+(P40*Assumptions!$B$17) -> 0.95756 | V40: =T40-U40 -> -0.83229973 | W40: =C40+(P40*Assumptions!$B$15) -> 1819.339 | X40: =V40/W40 -> -0.00045747369 | Y40: =X40*(365/R40) -> -0.0083488948 | Z40: =IF(AND(R40>0,Y40 > Assumptions!$B$13), "ENTER", "DONT ENTER") -> DONT ENTER | AB40: =VLOOKUP(A40, Raw_Data_Reliance!AQ:BE, 8, FALSE) -> 1376.1 | AC40: =Assumptions!$B$32 -> 45930 | AD40: =AC40-A40 -> 53 | AE40: =C40*(1+(Assumptions!$B$13*AD40/365)) -> 1380.6105 | AF40: =AB40-AE40 -> -4.5104775 | AG40: =(C40*Assumptions!$B$16)+(AB40*Assumptions!$B$17) -> 0.95912 | AH40: =AF40-AG40 -> -5.4695975 | AI40: =C40+(AB40*Assumptions!$B$15) -> 1821.913 | AJ40: =AH40/AI40 -> -0.0030021178 | AK40: =AJ40*(365/AD40) -> -0.020674963 | AL40: =IF(AND(AD40>0,AK40 > Assumptions!$B$13), "ENTER", "DONT ENTER") -> DONT ENTER
A41: 45878 | B41: RELIANCE | C41: =VLOOKUP(A41, Raw_Data_Reliance!A:N, 8, FALSE) -> #N/A | P41: =VLOOKUP(A41, Raw_Data_Reliance!AB:AP, 8, FALSE) -> #N/A | Q41: =Assumptions!$B$31 -> 45897 | R41: =Q41-A41 -> 19 | S41: =C41*(1+(Assumptions!$B$19*R41/365)) -> #N/A | T41: =P41-S41 -> #N/A | U41: =(C41*Assumptions!$B$16)+(P41*Assumptions!$B$17) -> #N/A | V41: =T41-U41 -> #N/A | W41: =C41+(P41*Assumptions!$B$15) -> #N/A | X41: =V41/W41 -> #N/A | Y41: =X41*(365/R41) -> #N/A | Z41: =IF(AND(R41>0,Y41 > Assumptions!$B$13), "ENTER", "DONT ENTER") -> #N/A | AB41: =VLOOKUP(A41, Raw_Data_Reliance!AQ:BE, 8, FALSE) -> #N/A | AC41: =Assumptions!$B$32 -> 45930 | AD41: =AC41-A41 -> 52 | AE41: =C41*(1+(Assumptions!$B$13*AD41/365)) -> #N/A | AF41: =AB41-AE41 -> #N/A | AG41: =(C41*Assumptions!$B$16)+(AB41*Assumptions!$B$17) -> #N/A | AH41: =AF41-AG41 -> #N/A | AI41: =C41+(AB41*Assumptions!$B$15) -> #N/A | AJ41: =AH41/AI41 -> #N/A | AK41: =AJ41*(365/AD41) -> #N/A | AL41: =IF(AND(AD41>0,AK41 > Assumptions!$B$13), "ENTER", "DONT ENTER") -> #N/A
A42: 45879 | B42: RELIANCE | C42: =VLOOKUP(A42, Raw_Data_Reliance!A:N, 8, FALSE) -> #N/A | P42: =VLOOKUP(A42, Raw_Data_Reliance!AB:AP, 8, FALSE) -> #N/A | Q42: =Assumptions!$B$31 -> 45897 | R42: =Q42-A42 -> 18 | S42: =C42*(1+(Assumptions!$B$19*R42/365)) -> #N/A | T42: =P42-S42 -> #N/A | U42: =(C42*Assumptions!$B$16)+(P42*Assumptions!$B$17) -> #N/A | V42: =T42-U42 -> #N/A | W42: =C42+(P42*Assumptions!$B$15) -> #N/A | X42: =V42/W42 -> #N/A | Y42: =X42*(365/R42) -> #N/A | Z42: =IF(AND(R42>0,Y42 > Assumptions!$B$13), "ENTER", "DONT ENTER") -> #N/A | AB42: =VLOOKUP(A42, Raw_Data_Reliance!AQ:BE, 8, FALSE) -> #N/A | AC42: =Assumptions!$B$32 -> 45930 | AD42: =AC42-A42 -> 51 | AE42: =C42*(1+(Assumptions!$B$13*AD42/365)) -> #N/A | AF42: =AB42-AE42 -> #N/A | AG42: =(C42*Assumptions!$B$16)+(AB42*Assumptions!$B$17) -> #N/A | AH42: =AF42-AG42 -> #N/A | AI42: =C42+(AB42*Assumptions!$B$15) -> #N/A | AJ42: =AH42/AI42 -> #N/A | AK42: =AJ42*(365/AD42) -> #N/A | AL42: =IF(AND(AD42>0,AK42 > Assumptions!$B$13), "ENTER", "DONT ENTER") -> #N/A
A43: 45880 | B43: RELIANCE | C43: =VLOOKUP(A43, Raw_Data_Reliance!A:N, 8, FALSE) -> 1386.2 | P43: =VLOOKUP(A43, Raw_Data_Reliance!AB:AP, 8, FALSE) -> 1383.1 | Q43: =Assumptions!$B$31 -> 45897 | R43: =Q43-A43 -> 17 | S43: =C43*(1+(Assumptions!$B$19*R43/365)) -> 1386.5228 | T43: =P43-S43 -> -3.4228137 | U43: =(C43*Assumptions!$B$16)+(P43*Assumptions!$B$17) -> 0.96972 | V43: =T43-U43 -> -4.3925337 | W43: =C43+(P43*Assumptions!$B$15) -> 1842.623 | X43: =V43/W43 -> -0.0023838483 | Y43: =X43*(365/R43) -> -0.051182625 | Z43: =IF(AND(R43>0,Y43 > Assumptions!$B$13), "ENTER", "DONT ENTER") -> DONT ENTER | AB43: =VLOOKUP(A43, Raw_Data_Reliance!AQ:BE, 8, FALSE) -> 1390.4 | AC43: =Assumptions!$B$32 -> 45930 | AD43: =AC43-A43 -> 50 | AE43: =C43*(1+(Assumptions!$B$13*AD43/365)) -> 1398.4479 | AF43: =AB43-AE43 -> -8.0479315 | AG43: =(C43*Assumptions!$B$16)+(AB43*Assumptions!$B$17) -> 0.97118 | AH43: =AF43-AG43 -> -9.0191115 | AI43: =C43+(AB43*Assumptions!$B$15) -> 1845.032 | AJ43: =AH43/AI43 -> -0.0048883225 | AK43: =AJ43*(365/AD43) -> -0.035684755 | AL43: =IF(AND(AD43>0,AK43 > Assumptions!$B$13), "ENTER", "DONT ENTER") -> DONT ENTER
A44: 45881 | B44: RELIANCE | C44: =VLOOKUP(A44, Raw_Data_Reliance!A:N, 8, FALSE) -> 1380.4 | P44: =VLOOKUP(A44, Raw_Data_Reliance!AB:AP, 8, FALSE) -> 1380 | Q44: =Assumptions!$B$31 -> 45897 | R44: =Q44-A44 -> 16 | S44: =C44*(1+(Assumptions!$B$19*R44/365)) -> 1380.7026 | T44: =P44-S44 -> -0.70255342 | U44: =(C44*Assumptions!$B$16)+(P44*Assumptions!$B$17) -> 0.9662 | V44: =T44-U44 -> -1.6687534 | W44: =C44+(P44*Assumptions!$B$15) -> 1835.8 | X44: =V44/W44 -> -0.00090900611 | Y44: =X44*(365/R44) -> -0.020736702 | Z44: =IF(AND(R44>0,Y44 > Assumptions!$B$13), "ENTER", "DONT ENTER") -> DONT ENTER | AB44: =VLOOKUP(A44, Raw_Data_Reliance!AQ:BE, 8, FALSE) -> 1387.8 | AC44: =Assumptions!$B$32 -> 45930 | AD44: =AC44-A44 -> 49 | AE44: =C44*(1+(Assumptions!$B$13*AD44/365)) -> 1392.3528 | AF44: =AB44-AE44 -> -4.5527512 | AG44: =(C44*Assumptions!$B$16)+(AB44*Assumptions!$B$17) -> 0.96776 | AH44: =AF44-AG44 -> -5.5205112 | AI44: =C44+(AB44*Assumptions!$B$15) -> 1838.374 | AJ44: =AH44/AI44 -> -0.0030029315 | AK44: =AJ44*(365/AD44) -> -0.022368776 | AL44: =IF(AND(AD44>0,AK44 > Assumptions!$B$13), "ENTER", "DONT ENTER") -> DONT ENTER
... A60: 45897 | B60: RELIANCE | C60: =VLOOKUP(A60, Raw_Data_Reliance!A:N, 8, FALSE) -> 1385.9 | P60: =VLOOKUP(A60, Raw_Data_Reliance!AB:AP, 8, FALSE) -> 1387.6 | Q60: =Assumptions!$B$31 -> 45897 | R60: =Q60-A60 -> 0 | S60: =C60*(1+(Assumptions!$B$19*R60/365)) -> 1385.9 | T60: =P60-S60 -> 1.7 | U60: =(C60*Assumptions!$B$16)+(P60*Assumptions!$B$17) -> 0.97047 | V60: =T60-U60 -> 0.72953 | W60: =C60+(P60*Assumptions!$B$15) -> 1843.808 | X60: =V60/W60 -> 0.00039566484 | Y60: =X60*(365/R60) -> #DIV/0! | Z60: =IF(AND(R60>0,Y60 > Assumptions!$B$13), "ENTER", "DONT ENTER") -> #DIV/0! | AB60: =VLOOKUP(A60, Raw_Data_Reliance!AQ:BE, 8, FALSE) -> 1395.4 | AC60: =Assumptions!$B$32 -> 45930 | AD60: =AC60-A60 -> 33 | AE60: =C60*(1+(Assumptions!$B$13*AD60/365)) -> 1393.9819 | AF60: =AB60-AE60 -> 1.4181147 | AG60: =(C60*Assumptions!$B$16)+(AB60*Assumptions!$B$17) -> 0.97203 | AH60: =AF60-AG60 -> 0.44608466 | AI60: =C60+(AB60*Assumptions!$B$15) -> 1846.382 | AJ60: =AH60/AI60 -> 0.00024159933 | AK60: =AJ60*(365/AD60) -> 0.002672235 | AL60: =IF(AND(AD60>0,AK60 > Assumptions!$B$13), "ENTER", "DONT ENTER") -> DONT ENTER
A61: 45898 | B61: RELIANCE | C61: =VLOOKUP(A61, Raw_Data_Reliance!A:N, 8, FALSE) -> 1357.2 | AB61: =VLOOKUP(A61, Raw_Data_Reliance!AQ:BE, 8, FALSE) -> 1364.4 | AC61: =Assumptions!$B$32 -> 45930 | AD61: =AC61-A61 -> 32 | AE61: =C61*(1+(Assumptions!$B$13*AD61/365)) -> 1364.8747 | AF61: =AB61-AE61 -> -0.47468712 | AG61: =(C61*Assumptions!$B$16)+(AB61*Assumptions!$B$17) -> 0.95148 | AH61: =AF61-AG61 -> -1.4261671 | AI61: =C61+(AB61*Assumptions!$B$15) -> 1807.452 | AJ61: =AH61/AI61 -> -0.00078904841 | AK61: =AJ61*(365/AD61) -> -0.0090000834 | AL61: =IF(AND(AD61>0,AK61 > Assumptions!$B$13), "ENTER", "DONT ENTER") -> DONT ENTER
A62: 45899 | B62: RELIANCE | C62: =VLOOKUP(A62, Raw_Data_Reliance!A:N, 8, FALSE) -> #N/A | AB62: =VLOOKUP(A62, Raw_Data_Reliance!AQ:BE, 8, FALSE) -> #N/A | AC62: =Assumptions!$B$32 -> 45930 | AD62: =AC62-A62 -> 31 | AE62: =C62*(1+(Assumptions!$B$13*AD62/365)) -> #N/A | AF62: =AB62-AE62 -> #N/A | AG62: =(C62*Assumptions!$B$16)+(AB62*Assumptions!$B$17) -> #N/A | AH62: =AF62-AG62 -> #N/A | AI62: =C62+(AB62*Assumptions!$B$15) -> #N/A | AJ62: =AH62/AI62 -> #N/A | AK62: =AJ62*(365/AD62) -> #N/A | AL62: =IF(AND(AD62>0,AK62 > Assumptions!$B$13), "ENTER", "DONT ENTER") -> #N/A
A63: 45900 | B63: RELIANCE | C63: =VLOOKUP(A63, Raw_Data_Reliance!A:N, 8, FALSE) -> #N/A | AB63: =VLOOKUP(A63, Raw_Data_Reliance!AQ:BE, 8, FALSE) -> #N/A | AC63: =Assumptions!$B$32 -> 45930 | AD63: =AC63-A63 -> 30 | AE63: =C63*(1+(Assumptions!$B$13*AD63/365)) -> #N/A | AF63: =AB63-AE63 -> #N/A | AG63: =(C63*Assumptions!$B$16)+(AB63*Assumptions!$B$17) -> #N/A | AH63: =AF63-AG63 -> #N/A | AI63: =C63+(AB63*Assumptions!$B$15) -> #N/A | AJ63: =AH63/AI63 -> #N/A | AK63: =AJ63*(365/AD63) -> #N/A | AL63: =IF(AND(AD63>0,AK63 > Assumptions!$B$13), "ENTER", "DONT ENTER") -> #N/A
A64: 45901 | B64: RELIANCE | C64: =VLOOKUP(A64, Raw_Data_Reliance!A:N, 8, FALSE) -> 1353.9 | AB64: =VLOOKUP(A64, Raw_Data_Reliance!AQ:BE, 8, FALSE) -> 1360.5 | AC64: =Assumptions!$B$32 -> 45930 | AD64: =AC64-A64 -> 29 | AE64: =C64*(1+(Assumptions!$B$13*AD64/365)) -> 1360.8383 | AF64: =AB64-AE64 -> -0.33827384 | AG64: =(C64*Assumptions!$B$16)+(AB64*Assumptions!$B$17) -> 0.94905 | AH64: =AF64-AG64 -> -1.2873238 | AI64: =C64+(AB64*Assumptions!$B$15) -> 1802.865 | AJ64: =AH64/AI64 -> -0.00071404339 | AK64: =AJ64*(365/AD64) -> -0.0089870978 | AL64: =IF(AND(AD64>0,AK64 > Assumptions!$B$13), "ENTER", "DONT ENTER") -> DONT ENTER
A65: 45902 | B65: RELIANCE | C65: =VLOOKUP(A65, Raw_Data_Reliance!A:N, 8, FALSE) -> 1366.5 | AB65: =VLOOKUP(A65, Raw_Data_Reliance!AQ:BE, 8, FALSE) -> 1372.6 | AC65: =Assumptions!$B$32 -> 45930 | AD65: =AC65-A65 -> 28 | AE65: =C65*(1+(Assumptions!$B$13*AD65/365)) -> 1373.2614 | AF65: =AB65-AE65 -> -0.66136712 | AG65: =(C65*Assumptions!$B$16)+(AB65*Assumptions!$B$17) -> 0.95777 | AH65: =AF65-AG65 -> -1.6191371 | AI65: =C65+(AB65*Assumptions!$B$15) -> 1819.458 | AJ65: =AH65/AI65 -> -0.0008899008 | AK65: =AJ65*(365/AD65) -> -0.011600493 | AL65: =IF(AND(AD65>0,AK65 > Assumptions!$B$13), "ENTER", "DONT ENTER") -> DONT ENTER
A66: 45903 | B66: RELIANCE | C66: =VLOOKUP(A66, Raw_Data_Reliance!A:N, 8, FALSE) -> 1372.6 | AB66: =VLOOKUP(A66, Raw_Data_Reliance!AQ:BE, 8, FALSE) -> 1377.2 | AC66: =Assumptions!$B$32 -> 45930 | AD66: =AC66-A66 -> 27 | AE66: =C66*(1+(Assumptions!$B$13*AD66/365)) -> 1379.149 | AF66: =AB66-AE66 -> -1.9489942 | AG66: =(C66*Assumptions!$B$16)+(AB66*Assumptions!$B$17) -> 0.96174 | AH66: =AF66-AG66 -> -2.9107342 | AI66: =C66+(AB66*Assumptions!$B$15) -> 1827.076 | AJ66: =AH66/AI66 -> -0.0015931107 | AK66: =AJ66*(365/AD66) -> -0.021536496 | AL66: =IF(AND(AD66>0,AK66 > Assumptions!$B$13), "ENTER", "DONT ENTER") -> DONT ENTER
A67: 45904 | B67: RELIANCE | C67: =VLOOKUP(A67, Raw_Data_Reliance!A:N, 8, FALSE) -> 1359.3 | AB67: =VLOOKUP(A67, Raw_Data_Reliance!AQ:BE, 8, FALSE) -> 1365.9 | AC67: =Assumptions!$B$32 -> 45930 | AD67: =AC67-A67 -> 26 | AE67: =C67*(1+(Assumptions!$B$13*AD67/365)) -> 1365.5453 | AF67: =AB67-AE67 -> 0.35466822 | AG67: =(C67*Assumptions!$B$16)+(AB67*Assumptions!$B$17) -> 0.95283 | AH67: =AF67-AG67 -> -0.59816178 | AI67: =C67+(AB67*Assumptions!$B$15) -> 1810.047 | AJ67: =AH67/AI67 -> -0.00033046754 | AK67: =AJ67*(365/AD67) -> -0.0046392559 | AL67: =IF(AND(AD67>0,AK67 > Assumptions!$B$13), "ENTER", "DONT ENTER") -> DONT ENTER
A68: 45905 | B68: RELIANCE | C68: =VLOOKUP(A68, Raw_Data_Reliance!A:N, 8, FALSE) -> 1375 | AB68: =VLOOKUP(A68, Raw_Data_Reliance!AQ:BE, 8, FALSE) -> 1378.6 | AC68: =Assumptions!$B$32 -> 45930 | AD68: =AC68-A68 -> 25 | AE68: =C68*(1+(Assumptions!$B$13*AD68/365)) -> 1381.0745 | AF68: =AB68-AE68 -> -2.4744863 | AG68: =(C68*Assumptions!$B$16)+(AB68*Assumptions!$B$17) -> 0.96322 | AH68: =AF68-AG68 -> -3.4377063 | AI68: =C68+(AB68*Assumptions!$B$15) -> 1829.938 | AJ68: =AH68/AI68 -> -0.0018785917 | AK68: =AJ68*(365/AD68) -> -0.027427439 | AL68: =IF(AND(AD68>0,AK68 > Assumptions!$B$13), "ENTER", "DONT ENTER") -> DONT ENTER
A69: 45906 | B69: RELIANCE | C69: =VLOOKUP(A69, Raw_Data_Reliance!A:N, 8, FALSE) -> #N/A | AB69: =VLOOKUP(A69, Raw_Data_Reliance!AQ:BE, 8, FALSE) -> #N/A | AC69: =Assumptions!$B$32 -> 45930 | AD69: =AC69-A69 -> 24 | AE69: =C69*(1+(Assumptions!$B$13*AD69/365)) -> #N/A | AF69: =AB69-AE69 -> #N/A | AG69: =(C69*Assumptions!$B$16)+(AB69*Assumptions!$B$17) -> #N/A | AH69: =AF69-AG69 -> #N/A | AI69: =C69+(AB69*Assumptions!$B$15) -> #N/A | AJ69: =AH69/AI69 -> #N/A | AK69: =AJ69*(365/AD69) -> #N/A | AL69: =IF(AND(AD69>0,AK69 > Assumptions!$B$13), "ENTER", "DONT ENTER") -> #N/A
A70: 45907 | B70: RELIANCE | C70: =VLOOKUP(A70, Raw_Data_Reliance!A:N, 8, FALSE) -> #N/A | AB70: =VLOOKUP(A70, Raw_Data_Reliance!AQ:BE, 8, FALSE) -> #N/A | AC70: =Assumptions!$B$32 -> 45930 | AD70: =AC70-A70 -> 23 | AE70: =C70*(1+(Assumptions!$B$13*AD70/365)) -> #N/A | AF70: =AB70-AE70 -> #N/A | AG70: =(C70*Assumptions!$B$16)+(AB70*Assumptions!$B$17) -> #N/A | AH70: =AF70-AG70 -> #N/A | AI70: =C70+(AB70*Assumptions!$B$15) -> #N/A | AJ70: =AH70/AI70 -> #N/A | AK70: =AJ70*(365/AD70) -> #N/A | AL70: =IF(AND(AD70>0,AK70 > Assumptions!$B$13), "ENTER", "DONT ENTER") -> #N/A
A71: 45908 | B71: RELIANCE | C71: =VLOOKUP(A71, Raw_Data_Reliance!A:N, 8, FALSE) -> 1378.5 | AB71: =VLOOKUP(A71, Raw_Data_Reliance!AQ:BE, 8, FALSE) -> 1382.3 | AC71: =Assumptions!$B$32 -> 45930 | AD71: =AC71-A71 -> 22 | AE71: =C71*(1+(Assumptions!$B$13*AD71/365)) -> 1383.8592 | AF71: =AB71-AE71 -> -1.5591548 | AG71: =(C71*Assumptions!$B$16)+(AB71*Assumptions!$B$17) -> 0.96571 | AH71: =AF71-AG71 -> -2.5248648 | AI71: =C71+(AB71*Assumptions!$B$15) -> 1834.659 | AJ71: =AH71/AI71 -> -0.0013762039 | AK71: =AJ71*(365/AD71) -> -0.022832473 | AL71: =IF(AND(AD71>0,AK71 > Assumptions!$B$13), "ENTER", "DONT ENTER") -> DONT ENTER
A72: 45909 | B72: RELIANCE | C72: =VLOOKUP(A72, Raw_Data_Reliance!A:N, 8, FALSE) -> 1376.2 | AB72: =VLOOKUP(A72, Raw_Data_Reliance!AQ:BE, 8, FALSE) -> 1380 | AC72: =Assumptions!$B$32 -> 45930 | AD72: =AC72-A72 -> 21 | AE72: =C72*(1+(Assumptions!$B$13*AD72/365)) -> 1381.307 | AF72: =AB72-AE72 -> -1.3070216 | AG72: =(C72*Assumptions!$B$16)+(AB72*Assumptions!$B$17) -> 0.9641 | AH72: =AF72-AG72 -> -2.2711216 | AI72: =C72+(AB72*Assumptions!$B$15) -> 1831.6 | AJ72: =AH72/AI72 -> -0.001239966 | AK72: =AJ72*(365/AD72) -> -0.021551789 | AL72: =IF(AND(AD72>0,AK72 > Assumptions!$B$13), "ENTER", "DONT ENTER") -> DONT ENTER
... A93: 45930 | B93: RELIANCE | C93: =VLOOKUP(A93, Raw_Data_Reliance!A:N, 8, FALSE) -> 1364 | AB93: =VLOOKUP(A93, Raw_Data_Reliance!AQ:BE, 8, FALSE) -> 1363.2 | AC93: =Assumptions!$B$32 -> 45930 | AD93: =AC93-A93 -> 0 | AE93: =C93*(1+(Assumptions!$B$13*AD93/365)) -> 1364 | AF93: =AB93-AE93 -> -0.8 | AG93: =(C93*Assumptions!$B$16)+(AB93*Assumptions!$B$17) -> 0.95464 | AH93: =AF93-AG93 -> -1.75464 | AI93: =C93+(AB93*Assumptions!$B$15) -> 1813.856 | AJ93: =AH93/AI93 -> -0.00096735353 | AK93: =AJ93*(365/AD93) -> #DIV/0! | AL93: =IF(AND(AD93>0,AK93 > Assumptions!$B$13), "ENTER", "DONT ENTER") -> #DIV/0!
...

Sheet Trade_Log
A1: Trade ID | B1: Stock | C1: Entry_Date | D1: Exit_Date | E1: Contract | F1: Lots | G1: Entry_Spot_Price | H1: Entry_Futures_Price | I1: Spot_Cost (Total cost of buying spot inventory) | J1: Margin Blocked | K1: Exit_Spot_Price | L1: Settlement_Value
A2: 1 | B2: =Assumptions!$A$24 -> RELIANCE | C2: ='Data Analysis'!A18 -> 45855 | D2: ='Data Analysis'!E18 -> 45869 | E2: =TEXT(D2,"mmm") -> Jul | F2: 37 | G2: =IFERROR(VLOOKUP(C2, 'Data Analysis'!$A:$C, 3, FALSE), 0) -> 1476.4 | H2: =IFERROR( IF(E2="JUL", VLOOKUP(C2, 'Data Analysis'!$A:$E, 4, FALSE), IF(E2="AUG", VLOOKUP(C2, 'Data Analysis'!$A:$Q, 16, FALSE), IF(E2="SEP", VLOOKUP(C2, 'Data Analysis'!$A:$AC, 28, FALSE), 0))), 0) -> 1482.6 | I2: =F2*Assumptions!$B$24*G2*(1+Assumptions!$B$16) -> 27327057 | J2: =F2*Assumptions!$B$24*H2*Assumptions!$B$18 -> 5485620 | K2: =IFERROR(VLOOKUP(D2, 'Data Analysis'!$A:$C, 3, FALSE), 0) -> 1390.2 | L2: =(F2*Assumptions!$B$24*K2*(1-Assumptions!$B$16)) + (F2*Assumptions!$B$24*(H2-K2)*(1-Assumptions!$B$17)) + J2 -> 32900519
A3: =A2+1 -> 2 | B3: =Assumptions!$A$24 -> RELIANCE | C3: ='Data Analysis'!A19 -> 45856 | D3: ='Data Analysis'!E19 -> 45869 | E3: =TEXT(D3,"mmm") -> Jul | F3: 34 | G3: =IFERROR(VLOOKUP(C3, 'Data Analysis'!$A:$C, 3, FALSE), 0) -> 1476 | H3: =IFERROR( IF(E3="JUL", VLOOKUP(C3, 'Data Analysis'!$A:$E, 4, FALSE), IF(E3="AUG", VLOOKUP(C3, 'Data Analysis'!$A:$Q, 16, FALSE), IF(E3="SEP", VLOOKUP(C3, 'Data Analysis'!$A:$AC, 28, FALSE), 0))), 0) -> 1482.6 | I3: =F3*Assumptions!$B$24*G3*(1+Assumptions!$B$16) -> 25104546 | J3: =F3*Assumptions!$B$24*H3*Assumptions!$B$18 -> 5040840 | K3: =IFERROR(VLOOKUP(D3, 'Data Analysis'!$A:$C, 3, FALSE), 0) -> 1390.2 | L3: =(F3*Assumptions!$B$24*K3*(1-Assumptions!$B$16)) + (F3*Assumptions!$B$24*(H3-K3)*(1-Assumptions!$B$17)) + J3 -> 30232909
A4: =A3+1 -> 3 | B4: =Assumptions!$A$24 -> RELIANCE | C4: ='Data Analysis'!A23 -> 45860 | D4: ='Data Analysis'!E23 -> 45869 | E4: =TEXT(D4,"mmm") -> Jul | F4: 19 | G4: =IFERROR(VLOOKUP(C4, 'Data Analysis'!$A:$C, 3, FALSE), 0) -> 1412.8 | H4: =IFERROR( IF(E4="JUL", VLOOKUP(C4, 'Data Analysis'!$A:$E, 4, FALSE), IF(E4="AUG", VLOOKUP(C4, 'Data Analysis'!$A:$Q, 16, FALSE), IF(E4="SEP", VLOOKUP(C4, 'Data Analysis'!$A:$AC, 28, FALSE), 0))), 0) -> 1417.3 | I4: =F4*Assumptions!$B$24*G4*(1+Assumptions!$B$16) -> 13428311 | J4: =F4*Assumptions!$B$24*H4*Assumptions!$B$18 -> 2692870 | K4: =IFERROR(VLOOKUP(D4, 'Data Analysis'!$A:$C, 3, FALSE), 0) -> 1390.2 | L4: =(F4*Assumptions!$B$24*K4*(1-Assumptions!$B$16)) + (F4*Assumptions!$B$24*(H4-K4)*(1-Assumptions!$B$17)) + J4 -> 16150565
A5: =A4+1 -> 4 | B5: =Assumptions!$A$24 -> RELIANCE | C5: ='Data Analysis'!A25 -> 45862 | D5: ='Data Analysis'!E25 -> 45869 | E5: =TEXT(D5,"mmm") -> Jul | F5: 6 | G5: =IFERROR(VLOOKUP(C5, 'Data Analysis'!$A:$C, 3, FALSE), 0) -> 1402.9 | H5: =IFERROR( IF(E5="JUL", VLOOKUP(C5, 'Data Analysis'!$A:$E, 4, FALSE), IF(E5="AUG", VLOOKUP(C5, 'Data Analysis'!$A:$Q, 16, FALSE), IF(E5="SEP", VLOOKUP(C5, 'Data Analysis'!$A:$AC, 28, FALSE), 0))), 0) -> 1406.6 | I5: =F5*Assumptions!$B$24*G5*(1+Assumptions!$B$16) -> 4210804.3 | J5: =F5*Assumptions!$B$24*H5*Assumptions!$B$18 -> 843960 | K5: =IFERROR(VLOOKUP(D5, 'Data Analysis'!$A:$C, 3, FALSE), 0) -> 1390.2 | L5: =(F5*Assumptions!$B$24*K5*(1-Assumptions!$B$16)) + (F5*Assumptions!$B$24*(H5-K5)*(1-Assumptions!$B$17)) + J5 -> 5061664.9
A6: =A5+1 -> 5 | B6: =Assumptions!$A$24 -> RELIANCE | C6: ='Data Analysis'!A50 -> 45887 | D6: ='Data Analysis'!Q51 -> 45897 | E6: =TEXT(D6,"mmm") -> Aug | F6: 39 | G6: =IFERROR(VLOOKUP(C6, 'Data Analysis'!$A:$C, 3, FALSE), 0) -> 1381.7 | H6: =IFERROR( IF(E6="JUL", VLOOKUP(C6, 'Data Analysis'!$A:$E, 4, FALSE), IF(E6="AUG", VLOOKUP(C6, 'Data Analysis'!$A:$Q, 16, FALSE), IF(E6="SEP", VLOOKUP(C6, 'Data Analysis'!$A:$AC, 28, FALSE), 0))), 0) -> 1386.6 | I6: =F6*Assumptions!$B$24*G6*(1+Assumptions!$B$16) -> 26956622 | J6: =F6*Assumptions!$B$24*H6*Assumptions!$B$18 -> 5407740 | K6: =IFERROR(VLOOKUP(D6, 'Data Analysis'!$A:$C, 3, FALSE), 0) -> 1385.9 | L6: =(F6*Assumptions!$B$24*K6*(1-Assumptions!$B$16)) + (F6*Assumptions!$B$24*(H6-K6)*(1-Assumptions!$B$17)) + J6 -> 32432925
A7: =A6+1 -> 6 | B7: =Assumptions!$A$24 -> RELIANCE | C7: ='Data Analysis'!A86 -> 45923 | D7: ='Data Analysis'!AC86 -> 45930 | E7: =TEXT(D7,"mmm") -> Sep | F7: 39 | G7: =IFERROR(VLOOKUP(C7, 'Data Analysis'!$A:$C, 3, FALSE), 0) -> 1389.8 | H7: =IFERROR( IF(E7="JUL", VLOOKUP(C7, 'Data Analysis'!$A:$E, 4, FALSE), IF(E7="AUG", VLOOKUP(C7, 'Data Analysis'!$A:$Q, 16, FALSE), IF(E7="SEP", VLOOKUP(C7, 'Data Analysis'!$A:$AC, 28, FALSE), 0))), 0) -> 1394.9 | I7: =F7*Assumptions!$B$24*G7*(1+Assumptions!$B$16) -> 27114651 | J7: =F7*Assumptions!$B$24*H7*Assumptions!$B$18 -> 5440110 | K7: =IFERROR(VLOOKUP(D7, 'Data Analysis'!$A:$C, 3, FALSE), 0) -> 1364 | L7: =(F7*Assumptions!$B$24*K7*(1-Assumptions!$B$16)) + (F7*Assumptions!$B$24*(H7-K7)*(1-Assumptions!$B$17)) + J7 -> 32627240
A8: =A7+1 -> 7 | B8: =Assumptions!$A$24 -> RELIANCE | C8: ='Data Analysis'!A88 -> 45925 | D8: ='Data Analysis'!AC88 -> 45930 | E8: =TEXT(D8,"mmm") -> Sep | F8: 20 | G8: =IFERROR(VLOOKUP(C8, 'Data Analysis'!$A:$C, 3, FALSE), 0) -> 1372.4 | H8: =IFERROR( IF(E8="JUL", VLOOKUP(C8, 'Data Analysis'!$A:$E, 4, FALSE), IF(E8="AUG", VLOOKUP(C8, 'Data Analysis'!$A:$Q, 16, FALSE), IF(E8="SEP", VLOOKUP(C8, 'Data Analysis'!$A:$AC, 28, FALSE), 0))), 0) -> 1376.6 | I8: =F8*Assumptions!$B$24*G8*(1+Assumptions!$B$16) -> 13730862 | J8: =F8*Assumptions!$B$24*H8*Assumptions!$B$18 -> 2753200 | K8: =IFERROR(VLOOKUP(D8, 'Data Analysis'!$A:$C, 3, FALSE), 0) -> 1364 | L8: =(F8*Assumptions!$B$24*K8*(1-Assumptions!$B$16)) + (F8*Assumptions!$B$24*(H8-K8)*(1-Assumptions!$B$17)) + J8 -> 16512355
A9: =A8+1 -> 8 | B9: =Assumptions!$A$25 -> ADANI | C9: ='Data Analysis'!A116 -> 45861 | D9: ='Data Analysis'!E121 -> 45869 | E9: =TEXT(D9,"mmm") -> Jul | F9: 9 | G9: {=IFERROR( INDEX('Data Analysis'!$C:$C, SMALL( IF('Data Analysis'!$A:$A=C9, ROW('Data Analysis'!$A:$A)), 2) ), 0)} -> 2614.5 | H9: {=IFERROR( IF(E9="JUL", INDEX('Data Analysis'!$D:$D, SMALL(IF('Data Analysis'!$A:$A=C9, ROW('Data Analysis'!$A:$A)), 2)), IF(E9="AUG", INDEX('Data Analysis'!$P:$P, SMALL(IF('Data Analysis'!$A:$A=C9, ROW('Data Analysis'!$A:$A)), 2)), IF(E9="SEP", INDEX('Data Analysis'!$AB:$AB, SMALL(IF('Data Analysis'!$A:$A=C9, ROW('Data Analysis'!$A:$A)), 2)), 0))), 0)} -> 2621.8 | I9: =F9*Assumptions!$B$25*G9*(1+Assumptions!$B$16) -> 7062679.6 | J9: =F9*Assumptions!$B$25*H9*Assumptions!$B$18 -> 1415772 | K9: {=IFERROR( INDEX('Data Analysis'!$C:$C, SMALL( IF('Data Analysis'!$A:$A=D9, ROW('Data Analysis'!$A:$A)), 2) ), 0)} -> 2430.7 | L9: =(F9*Assumptions!$B$25*K9*(1-Assumptions!$B$16)) + (F9*Assumptions!$B$25*(H9-K9)*(1-Assumptions!$B$17)) + J9 -> 8491247.4
A10: =A9+1 -> 9 | B10: =Assumptions!$A$25 -> ADANI | C10: ='Data Analysis'!A122 -> 45867 | D10: ='Data Analysis'!E122 -> 45869 | E10: =TEXT(D10,"mmm") -> Jul | F10: 3 | G10: {=IFERROR( INDEX('Data Analysis'!$C:$C, SMALL( IF('Data Analysis'!$A:$A=C10, ROW('Data Analysis'!$A:$A)), 2) ), 0)} -> 2547.9 | H10: {=IFERROR( IF(E10="JUL", INDEX('Data Analysis'!$D:$D, SMALL(IF('Data Analysis'!$A:$A=C10, ROW('Data Analysis'!$A:$A)), 2)), IF(E10="AUG", INDEX('Data Analysis'!$P:$P, SMALL(IF('Data Analysis'!$A:$A=C10, ROW('Data Analysis'!$A:$A)), 2)), IF(E10="SEP", INDEX('Data Analysis'!$AB:$AB, SMALL(IF('Data Analysis'!$A:$A=C10, ROW('Data Analysis'!$A:$A)), 2)), 0))), 0)} -> 2552.4 | I10: =F10*Assumptions!$B$25*G10*(1+Assumptions!$B$16) -> 2294256.6 | J10: =F10*Assumptions!$B$25*H10*Assumptions!$B$18 -> 459432 | K10: {=IFERROR( INDEX('Data Analysis'!$C:$C, SMALL( IF('Data Analysis'!$A:$A=D10, ROW('Data Analysis'!$A:$A)), 2) ), 0)} -> 2430.7 | L10: =(F10*Assumptions!$B$25*K10*(1-Assumptions!$B$16)) + (F10*Assumptions!$B$25*(H10-K10)*(1-Assumptions!$B$17)) + J10 -> 2755476.3
A11: =A10+1 -> 10 | B11: =Assumptions!$A$25 -> ADANI | C11: ='Data Analysis'!A179 -> 45924 | D11: ='Data Analysis'!AC179 -> 45930 | E11: =TEXT(D11,"mmm") -> Sep | F11: 32 | G11: {=IFERROR( INDEX('Data Analysis'!$C:$C, SMALL( IF('Data Analysis'!$A:$A=C11, ROW('Data Analysis'!$A:$A)), 2) ), 0)} -> 2619.8 | H11: {=IFERROR( IF(E11="JUL", INDEX('Data Analysis'!$D:$D, SMALL(IF('Data Analysis'!$A:$A=C11, ROW('Data Analysis'!$A:$A)), 2)), IF(E11="AUG", INDEX('Data Analysis'!$P:$P, SMALL(IF('Data Analysis'!$A:$A=C11, ROW('Data Analysis'!$A:$A)), 2)), IF(E11="SEP", INDEX('Data Analysis'!$AB:$AB, SMALL(IF('Data Analysis'!$A:$A=C11, ROW('Data Analysis'!$A:$A)), 2)), 0))), 0)} -> 2628.7 | I11: =F11*Assumptions!$B$25*G11*(1+Assumptions!$B$16) -> 25162655 | J11: =F11*Assumptions!$B$25*H11*Assumptions!$B$18 -> 5047104 | K11: {=IFERROR( INDEX('Data Analysis'!$C:$C, SMALL( IF('Data Analysis'!$A:$A=D11, ROW('Data Analysis'!$A:$A)), 2) ), 0)} -> 2505.9 | L11: =(F11*Assumptions!$B$25*K11*(1-Assumptions!$B$16)) + (F11*Assumptions!$B$25*(H11-K11)*(1-Assumptions!$B$17)) + J11 -> 30270360
A12: =A11+1 -> 11 | B12: =Assumptions!$A$25 -> ADANI | C12: ='Data Analysis'!A180 -> 45925 | D12: ='Data Analysis'!AC180 -> 45930 | E12: =TEXT(D12,"mmm") -> Sep | F12: 10 | G12: {=IFERROR( INDEX('Data Analysis'!$C:$C, SMALL( IF('Data Analysis'!$A:$A=C12, ROW('Data Analysis'!$A:$A)), 2) ), 0)} -> 2576.4 | H12: {=IFERROR( IF(E12="JUL", INDEX('Data Analysis'!$D:$D, SMALL(IF('Data Analysis'!$A:$A=C12, ROW('Data Analysis'!$A:$A)), 2)), IF(E12="AUG", INDEX('Data Analysis'!$P:$P, SMALL(IF('Data Analysis'!$A:$A=C12, ROW('Data Analysis'!$A:$A)), 2)), IF(E12="SEP", INDEX('Data Analysis'!$AB:$AB, SMALL(IF('Data Analysis'!$A:$A=C12, ROW('Data Analysis'!$A:$A)), 2)), 0))), 0)} -> 2586 | I12: =F12*Assumptions!$B$25*G12*(1+Assumptions!$B$16) -> 7733064.6 | J12: =F12*Assumptions!$B$25*H12*Assumptions!$B$18 -> 1551600 | K12: {=IFERROR( INDEX('Data Analysis'!$C:$C, SMALL( IF('Data Analysis'!$A:$A=D12, ROW('Data Analysis'!$A:$A)), 2) ), 0)} -> 2505.9 | L12: =(F12*Assumptions!$B$25*K12*(1-Assumptions!$B$16)) + (F12*Assumptions!$B$25*(H12-K12)*(1-Assumptions!$B$17)) + J12 -> 9305793.1
A13: =A12+1 -> 12 | B13: =Assumptions!$A$25 -> ADANI | C13: ='Data Analysis'!A184 -> 45929 | D13: ='Data Analysis'!AC184 -> 45930 | E13: =TEXT(D13,"mmm") -> Sep | F13: 5 | G13: {=IFERROR( INDEX('Data Analysis'!$C:$C, SMALL( IF('Data Analysis'!$A:$A=C13, ROW('Data Analysis'!$A:$A)), 2) ), 0)} -> 2509.5 | H13: {=IFERROR( IF(E13="JUL", INDEX('Data Analysis'!$D:$D, SMALL(IF('Data Analysis'!$A:$A=C13, ROW('Data Analysis'!$A:$A)), 2)), IF(E13="AUG", INDEX('Data Analysis'!$P:$P, SMALL(IF('Data Analysis'!$A:$A=C13, ROW('Data Analysis'!$A:$A)), 2)), IF(E13="SEP", INDEX('Data Analysis'!$AB:$AB, SMALL(IF('Data Analysis'!$A:$A=C13, ROW('Data Analysis'!$A:$A)), 2)), 0))), 0)} -> 2516 | I13: =F13*Assumptions!$B$25*G13*(1+Assumptions!$B$16) -> 3766132.1 | J13: =F13*Assumptions!$B$25*H13*Assumptions!$B$18 -> 754800 | K13: {=IFERROR( INDEX('Data Analysis'!$C:$C, SMALL( IF('Data Analysis'!$A:$A=D13, ROW('Data Analysis'!$A:$A)), 2) ), 0)} -> 2505.9 | L13: =(F13*Assumptions!$B$25*K13*(1-Assumptions!$B$16)) + (F13*Assumptions!$B$25*(H13-K13)*(1-Assumptions!$B$17)) + J13 -> 4526917.5

Sheet Daily_Ledger
A1: Date | B1: Opening_Cash | C1: New Spot Outflow | D1: New Margin Outflow | E1: New Trade Outflow | F1: Closed Trade Inflow | G1: Uninvested_Cash | H1: Interest_Earned | I1: Total_Spot_Inventory_Cost | J1: Total_Margin_Blocked | K1: Closing_Cash | L1: Total_Fund_Value
A2: 45839 | B2: =Assumptions!B4 -> 100000000 | C2: =SUMIF(Trade_Log!$C:$C, A2, Trade_Log!$I:$I) -> 0 | D2: =SUMIF(Trade_Log!$C:$C, A2, Trade_Log!$J:$J) -> 0 | E2: =-(C2+D2) -> 0 | F2: =SUMIF(Trade_Log!$D:$D, A2, Trade_Log!$L:$L) -> 0 | G2: =B2+E2+F2 -> 100000000 | H2: =G2*Assumptions!$B$5/365 -> 16438.356 | I2: =SUMIFS(Trade_Log!$I:$I, Trade_Log!$C:$C, "<="&A2, Trade_Log!$D:$D, ">"&A2) -> 0 | J2: =SUMIFS(Trade_Log!$J:$J, Trade_Log!$C:$C, "<="&A2, Trade_Log!$D:$D, ">"&A2) -> 0 | K2: =G2+H2 -> 1.0001644e+08 | L2: =K2+I2+J2 -> 1.0001644e+08
A3: 45840 | B3: =K2 -> 1.0001644e+08 | C3: =SUMIF(Trade_Log!$C:$C, A3, Trade_Log!$I:$I) -> 0 | D3: =SUMIF(Trade_Log!$C:$C, A3, Trade_Log!$J:$J) -> 0 | E3: =-(C3+D3) -> 0 | F3: =SUMIF(Trade_Log!$D:$D, A3, Trade_Log!$L:$L) -> 0 | G3: =B3+E3+F3 -> 1.0001644e+08 | H3: =G3*Assumptions!$B$5/365 -> 16441.058 | I3: =SUMIFS(Trade_Log!$I:$I, Trade_Log!$C:$C, "<="&A3, Trade_Log!$D:$D, ">"&A3) -> 0 | J3: =SUMIFS(Trade_Log!$J:$J, Trade_Log!$C:$C, "<="&A3, Trade_Log!$D:$D, ">"&A3) -> 0 | K3: =G3+H3 -> 1.0003288e+08 | L3: =K3+I3+J3 -> 1.0003288e+08
A4: 45841 | B4: =K3 -> 1.0003288e+08 | C4: =SUMIF(Trade_Log!$C:$C, A4, Trade_Log!$I:$I) -> 0 | D4: =SUMIF(Trade_Log!$C:$C, A4, Trade_Log!$J:$J) -> 0 | E4: =-(C4+D4) -> 0 | F4: =SUMIF(Trade_Log!$D:$D, A4, Trade_Log!$L:$L) -> 0 | G4: =B4+E4+F4 -> 1.0003288e+08 | H4: =G4*Assumptions!$B$5/365 -> 16443.761 | I4: =SUMIFS(Trade_Log!$I:$I, Trade_Log!$C:$C, "<="&A4, Trade_Log!$D:$D, ">"&A4) -> 0 | J4: =SUMIFS(Trade_Log!$J:$J, Trade_Log!$C:$C, "<="&A4, Trade_Log!$D:$D, ">"&A4) -> 0 | K4: =G4+H4 -> 1.0004932e+08 | L4: =K4+I4+J4 -> 1.0004932e+08
A5: 45842 | B5: =K4 -> 1.0004932e+08 | C5: =SUMIF(Trade_Log!$C:$C, A5, Trade_Log!$I:$I) -> 0 | D5: =SUMIF(Trade_Log!$C:$C, A5, Trade_Log!$J:$J) -> 0 | E5: =-(C5+D5) -> 0 | F5: =SUMIF(Trade_Log!$D:$D, A5, Trade_Log!$L:$L) -> 0 | G5: =B5+E5+F5 -> 1.0004932e+08 | H5: =G5*Assumptions!$B$5/365 -> 16446.464 | I5: =SUMIFS(Trade_Log!$I:$I, Trade_Log!$C:$C, "<="&A5, Trade_Log!$D:$D, ">"&A5) -> 0 | J5: =SUMIFS(Trade_Log!$J:$J, Trade_Log!$C:$C, "<="&A5, Trade_Log!$D:$D, ">"&A5) -> 0 | K5: =G5+H5 -> 1.0006577e+08 | L5: =K5+I5+J5 -> 1.0006577e+08
A6: 45843 | B6: =K5 -> 1.0006577e+08 | C6: =SUMIF(Trade_Log!$C:$C, A6, Trade_Log!$I:$I) -> 0 | D6: =SUMIF(Trade_Log!$C:$C, A6, Trade_Log!$J:$J) -> 0 | E6: =-(C6+D6) -> 0 | F6: =SUMIF(Trade_Log!$D:$D, A6, Trade_Log!$L:$L) -> 0 | G6: =B6+E6+F6 -> 1.0006577e+08 | H6: =G6*Assumptions!$B$5/365 -> 16449.168 | I6: =SUMIFS(Trade_Log!$I:$I, Trade_Log!$C:$C, "<="&A6, Trade_Log!$D:$D, ">"&A6) -> 0 | J6: =SUMIFS(Trade_Log!$J:$J, Trade_Log!$C:$C, "<="&A6, Trade_Log!$D:$D, ">"&A6) -> 0 | K6: =G6+H6 -> 1.0008222e+08 | L6: =K6+I6+J6 -> 1.0008222e+08
